<robot name="left_back_leg">
    <link name="world"/>
    
    <link name="link0">
        <visual>
            <origin xyz="0.0 0.0 0.0" rpy="0.0 0.0 0.0"/>
            <geometry>
                <cylinder radius="0.04825" length="0.049"/>
            </geometry>
            <material name="red">
                <color rgba="1.0 0.0 0.0 1.0"/>
            </material>
        </visual>
    </link>

    <link name="link1">
        <inertial>
            <origin xyz="0.0 -0.0068 0.5701" rpy="0.0 0.0 0.0"/>
            <mass value="0.768"/>
            <inertia
                ixx="0.003480040"
                ixy="0.000013893"
                ixz="-0.000004063"
                iyy="0.003819685"
                iyz="-0.000296469"
                izz="0.000754587"/>
        </inertial>
        <visual>
            <origin xyz="0.0 0.0 0.0" rpy="0.0 0.0 0.0"/>
            <geometry>
                <box size="0.114 0.067 0.067"/>
            </geometry>
            <material name="red">
                <color rgba="1.0 0.0 0.0 1.0"/>
            </material>
        </visual>
    </link>

    <link name="link2">
        <inertial>
            <origin xyz="0.041535 0.0 0.041108" rpy="0.0 0.0 0.0"/>
            <mass value="1.074"/>
            <inertia
                ixx="0.002961167"
                ixy="0.000177168"
                ixz="0.002631913"
                iyy="0.009715536"
                iyz="-0.000007216"
                izz="0.007936492"/>
        </inertial>
        <visual>
            <origin xyz="0.1 0.0 0.05" rpy="0.0 0.0 0.0"/>
            <geometry>
                <box size="0.25 0.05 0.10"/>
            </geometry>
            <material name="red">
                <color rgba="1.0 0.0 0.0 1.0"/>
            </material>
        </visual>
    </link>

    <link name="link3">
        <inertial>
            <origin xyz="0.175 0.0 0.0" rpy="0.0 0.0 0.0"/>
            <mass value="0.424"/>
            <inertia
                ixx="0.000079556"
                ixy="-0.000045712"
                ixz="-0.000009293"
                iyy="0.015978182"
                iyz="0.0"
                izz="0.016"/>
        </inertial>
        <visual>
            <origin xyz="0.12 0.0 0.0" rpy="0.0 0.0 0.0"/>
            <geometry>
                <box size="0.246 0.04 0.04"/>
            </geometry>
            <material name="red">
                <color rgba="1.0 0.0 0.0 1.0"/>
            </material>
        </visual>
    </link>

    <joint name="joint0" type="fixed">
        <origin xyz="0.115 -0.108 0.32" rpy="1.5708 1.5708 -1.5708"/>
        <parent link="world"/>
        <child link="link0"/>
    </joint>

    <joint name="joint1" type="revolute">
        <origin xyz="0.0 0.0 0.049" rpy="0.0 0.0 0.0"/>
        <parent link="link0"/>
        <child link="link1"/>
        <axis xyz="0.0 0.0 1.0"/>
        <limit lower="-3.14159265" upper="3.14159265" effort="10.0" velocity="1.0"/>
    </joint>

    <joint name="joint2" type="revolute">
        <origin xyz="0.0 -0.032 0.00" rpy="1.5708 -1.5708 0.0"/>
        <parent link="link1"/>
        <child link="link2"/>
        <axis xyz="0.0 0.0 1.0"/>
        <limit lower="-3.14159265" upper="3.14159265" effort="10.0" velocity="1.0"/>
    </joint>

    <joint name="joint3" type="revolute">
        <origin xyz="0.21 0.0 0.07" rpy="0.0 0.0 0.0"/>
        <parent link="link2"/>
        <child link="link3"/>
        <axis xyz="0.0 0.0 1.0"/>
        <limit lower="-3.14159265" upper="3.14159265" effort="10.0" velocity="1.0"/>
    </joint>

</robot>
